<?xml version="1.0" encoding="UTF-8"?>
<!-- Generated by org.testng.reporters.JUnitXMLReporter -->
<testsuite hostname="ShiekKhurram" ignored="0" name="Test" tests="9" failures="2" timestamp="06 Nov 2018 08:24:41 GMT" time="0.1" errors="0">
  <testcase name="test1" time="0.012" classname="RetryAnalyzerLogic.TestCase">
    <skipped/>
  </testcase> <!-- test1 -->
  <testcase name="test1" time="0.002" classname="RetryAnalyzerLogic.TestCase">
    <skipped/>
  </testcase> <!-- test1 -->
  <testcase name="test1" time="0.001" classname="RetryAnalyzerLogic.TestCase">
    <skipped/>
  </testcase> <!-- test1 -->
  <testcase name="test1" time="0.002" classname="RetryAnalyzerLogic.TestCase">
    <failure type="java.lang.AssertionError" message="expected [false] but found [true]">
      <![CDATA[java.lang.AssertionError: expected [false] but found [true]
at RetryAnalyzerLogic.TestCase.test1(TestCase.java:11)
... Removed 31 stack frames]]>
    </failure>
  </testcase> <!-- test1 -->
  <testcase name="test2" time="0.002" classname="RetryAnalyzerLogic.TestCase">
    <skipped/>
  </testcase> <!-- test2 -->
  <testcase name="test2" time="0.005" classname="RetryAnalyzerLogic.TestCase">
    <skipped/>
  </testcase> <!-- test2 -->
  <testcase name="test2" time="0.002" classname="RetryAnalyzerLogic.TestCase">
    <skipped/>
  </testcase> <!-- test2 -->
  <testcase name="test2" time="0.001" classname="RetryAnalyzerLogic.TestCase">
    <failure type="java.lang.AssertionError" message="expected [false] but found [true]">
      <![CDATA[java.lang.AssertionError: expected [false] but found [true]
at RetryAnalyzerLogic.TestCase.test2(TestCase.java:17)
... Removed 31 stack frames]]>
    </failure>
  </testcase> <!-- test2 -->
  <testcase name="test3" time="0.002" classname="RetryAnalyzerLogic.TestCase"/>
</testsuite> <!-- Test -->
